<mujoco model="ant">
  <compiler angle="degree" coordinate="local" inertiafromgeom="true"/>
  <option integrator="RK4" timestep="0.01"/>
  <custom>
    <numeric data="0.0 0.0 0.55 1.0 0.0 0.0 0.0 0.0 1.0 0.0 -1.0 0.0 -1.0 0.0 1.0" name="init_qpos"/>
  </custom>
  <default>
    <joint armature="1" damping="1" limited="true"/>
    <geom conaffinity="0" condim="3" density="5.0" friction="1 0.5 0.5" margin="0.01" rgba="0.8 0.6 0.4 1"/>
  </default>
  <asset>
    <texture builtin="gradient" height="100" rgb1="1 1 1" rgb2="0 0 0" type="skybox" width="100"/>
    <texture builtin="flat" height="1278" mark="cross" markrgb="1 1 1" name="texgeom" random="0.01" rgb1="0.8 0.6 0.4" rgb2="0.8 0.6 0.4" type="cube" width="127"/>
    <texture builtin="checker" height="100" name="texplane" rgb1="0 0 0" rgb2="0.8 0.8 0.8" type="2d" width="100"/>
    <material name="MatPlane" reflectance="0.5" shininess="1" specular="1" texrepeat="60 60" texture="texplane"/>
    <material name="geom" texture="texgeom" texuniform="true"/>
  </asset>
  <worldbody>
    <light cutoff="100" diffuse="1 1 1" dir="-0 0 -1.3" directional="true" exponent="1" pos="0 0 1.3" specular=".1 .1 .1"/>
    <geom conaffinity="1" condim="3" material="MatPlane" name="floor" pos="0 0 0" rgba="0.8 0.9 0.8 1" size="40 40 40" type="plane"/>
    <body name="torso" pos="0 0 0.75">
      <geom name="torsoGeom" pos="0 0 0" size="0.25" type="sphere"/>
      <joint name="rootJoint" armature="0" damping="0" limited="false" margin="0.01" pos="0 0 0" type="free"/>

      <body name="aux_1" pos="0.2 0.2 0">
        <joint name="hip_1" axis="0 0 1" pos="0.0 0.0 0.0" range="-30 30" type="hinge"/>
        <geom name="legGeom_1" fromto="0.0 0.0 0.0 0.2 0.2 0.0" size="0.08" type="capsule"/>
        <body name="f_1" pos="0.2 0.2 0">
          <joint name="ankle_1" axis="-1 1 0" pos="0.0 0.0 0.0" range="30 70" type="hinge"/>
          <geom name="ankleGeom_1" fromto="0.0 0.0 0.0 0.4 0.4 0.0" size="0.08" type="capsule"/>
        </body>
      </body>

      <body name="aux_2" pos="-0.2 0.2 0">
        <joint name="hip_2" axis="0 0 1" pos="0.0 0.0 0.0" range="-30 30" type="hinge"/>
        <geom name="legGeom_2" fromto="0.0 0.0 0.0 -0.2 0.2 0.0" size="0.08" type="capsule"/>
        <body name="f_2" pos="-0.2 0.2 0">
          <joint name="ankle_2" axis="1 1 0" pos="0.0 0.0 0.0" range="-70 -30" type="hinge"/>
          <geom name="ankleGeom_2" fromto="0.0 0.0 0.0 -0.4 0.4 0.0" size="0.08" type="capsule"/>
        </body>
      </body>

      <body name="aux_3" pos="-0.2 -0.2 0">
        <joint name="hip_3" axis="0 0 1" pos="0.0 0.0 0.0" range="-30 30" type="hinge"/>
        <geom name="legGeom_3" fromto="0.0 0.0 0.0 -0.2 -0.2 0.0" size="0.08" type="capsule"/>
        <body name="f_3" pos="-0.2 -0.2 0">
          <joint name="ankle_3" axis="-1 1 0" pos="0.0 0.0 0.0" range="-70 -30" type="hinge"/>
          <geom name="ankleGeom_3" fromto="0.0 0.0 0.0 -0.4 -0.4 0.0" size="0.08" type="capsule"/>
        </body>
      </body>
      <body name="aux_4" pos="0.2 -0.2 0">
        <joint name="hip_4" axis="0 0 1" pos="0.0 0.0 0.0" range="-30 30" type="hinge"/>
        <geom name="legGeom_4" fromto="0.0 0.0 0.0 0.2 -0.2 0.0" size="0.08" type="capsule"/>
        <body name="f_4" pos="0.2 -0.2 0">
          <joint name="ankle_4" axis="1 1 0" pos="0.0 0.0 0.0" range="30 70" type="hinge"/>
          <geom name="ankleGeom_4" fromto="0.0 0.0 0.0 0.4 -0.4 0.0" size="0.08" type="capsule"/>
        </body>
      </body>

    </body>
  </worldbody>
  <actuator>
    <motor ctrllimited="true" ctrlrange="-1.0 1.0" joint="hip_4" gear="150"/>
    <motor ctrllimited="true" ctrlrange="-1.0 1.0" joint="ankle_4" gear="150"/>
    <motor ctrllimited="true" ctrlrange="-1.0 1.0" joint="hip_1" gear="150"/>
    <motor ctrllimited="true" ctrlrange="-1.0 1.0" joint="ankle_1" gear="150"/>
    <motor ctrllimited="true" ctrlrange="-1.0 1.0" joint="hip_2" gear="150"/>
    <motor ctrllimited="true" ctrlrange="-1.0 1.0" joint="ankle_2" gear="150"/>
    <motor ctrllimited="true" ctrlrange="-1.0 1.0" joint="hip_3" gear="150"/>
    <motor ctrllimited="true" ctrlrange="-1.0 1.0" joint="ankle_3" gear="150"/>
  </actuator>
</mujoco>
